Workbook
Name age: [1]Parameters!$B$8
Name c_3rdIP: [2]Parameters!$B$9
Name c_3rdOP: [2]Parameters!$B$6
Name c_4thIP: [2]Parameters!$B$10
Name c_4thOP: [2]Parameters!$B$7
Name c_5thIP: [2]Parameters!$B$11
Name c_5thOP: [2]Parameters!$B$8
Name c_AUG: [2]Parameters!$B$18
Name c_COM: [2]Parameters!$B$19
Name c_ESK_HRU1: [2]Parameters!$B$12
Name c_ESK_HRU2: [2]Parameters!$B$13
Name c_ESK_HRU3: [2]Parameters!$B$14
Name c_ESK_TX1: [2]Parameters!$B$15
Name c_ESK_TX2: [2]Parameters!$B$16
Name c_ESK_TX3: [2]Parameters!$B$17
Name c_PSY: [2]Parameters!$B$20
Name c_rTMS: [2]Parameters!$B$21
Name cariprazine_ucost: Drug_costs!$B$6
Name cariprazine_udose: Drug_costs!$D$6
Name cDR: [1]Parameters!$B$11
Name cPrimary: [1]Parameters!$B$32
Name cRevision: [1]Parameters!$B$33
Name cStandard: [1]Parameters!$B$35
Name cSuccess: [1]Parameters!$B$34
Name Cycle_length: [2]Parameters!$B$2
Name d_rate: [2]Parameters!$B$43
Name esketamine_ucost: Drug_costs!$B$2
Name esketamine_udose: Drug_costs!$D$2
Name gamma: [1]Parameters!$B$26
Name injection_ucost: #REF!
Name lambda: [1]Parameters!$B$25
Name lifetable: '[1]Life tables'!$C$15:$E$20
Name male: [1]Parameters!$B$9
Name mean_age: 'Hypothetical population'!$B$3
Name mianserin_ucost: Drug_costs!$B$5
Name mianserin_udose: Drug_costs!$D$5
Name mirtazapine_ucost: Drug_costs!$B$4
Name mirtazapine_udose: Drug_costs!$D$4
Name Mode: [2]Parameters!$B$3
Name oDR: [1]Parameters!$B$12
Name olanzapine_ucost: Drug_costs!$B$3
Name olanzapine_udose: Drug_costs!$D$3
Name omrPTHR: [1]Parameters!$B$16
Name omrRTHR: [1]Parameters!$B$17
Name p_3rdREM2REL: [2]Parameters!$B$29
Name p_3rdRES2REL: [2]Parameters!$B$28
Name p_3rdTX2REM: [2]Parameters!$B$27
Name p_3rdTX2RES: [2]Parameters!$B$26
Name p_4thREM2REL: [2]Parameters!$B$33
Name p_4thRES2REL: [2]Parameters!$B$32
Name p_4thTX2REM: [2]Parameters!$B$31
Name p_4thTX2RES: [2]Parameters!$B$30
Name p_5thREM2REL: [2]Parameters!$B$37
Name p_5thRES2REL: [2]Parameters!$B$36
Name p_5thTX2REM: [2]Parameters!$B$35
Name p_5thTX2RES: [2]Parameters!$B$34
Name p_death1: [2]Parameters!$B$38
Name p_death2: [2]Parameters!$B$39
Name p_death3: [2]Parameters!$B$40
Name p_death4: [2]Parameters!$B$41

Sheet New_meta_Com_Aug
A1: Study | B1: Ratio | C1: Lower 95%CI | D1: Upper 95%CI | E1: Type | F1: Category | G1: Drug | H1: Doses | I1: Parameter
A2: Bauer 2009 (ONYX) | B2: 1.22 | C2: 1.01 | D2: 1.28 | E2: RR | F2: Augmentation | G2: Quetiapine | H2: Mixed | I2: Response
A3: Dunner 2007 | B3: 2.5 | C3: 0.6 | D3: 10.34 | E3: RR | F3: Augmentation | G3: Ziprasidone | H3: Mixed | I3: Response
A4: Durgam 2016 | B4: 1.27 | C4: 1.07 | D4: 1.52 | E4: RR | F4: Augmentation | G4: Cariprazine | H4: Mixed | I4: Response
A5: El-Khalili 2010 (PEARL) | B5: 1.24 | C5: 1.01 | D5: 1.52 | E5: RR | F5: Augmentation | G5: Quetiapine | H5: Mixed | I5: Response
A6: Ferreri 2001 | B6: 1.7 | C6: 1.03 | D6: 2.78 | E6: RR | F6: Combination | G6: Mianserin | H6: Fixed | I6: Response
A7: Kessler 2018 | B7: 1.22 | C7: 0.97 | D7: 1.54 | E7: RR | F7: Combination | G7: Mirtazapine | H7: Fixed | I7: Response
A8: McIntyre 2007 | B8: 1.75 | C8: 0.87 | D8: 3.52 | E8: RR | F8: Augmentation | G8: Quetiapine | H8: Mixed | I8: Response
A9: Papakostas 2015 | B9: 1.71 | C9: 0.97 | D9: 3 | E9: RR | F9: Augmentation | G9: Ziprasidone | H9: Mixed | I9: Response
A10: Shelton 2001 | B10: 6 | C10: 0.87 | D10: 41.21 | E10: RR | F10: Augmentation | G10: Olazapine | H10: Fixed | I10: Response
A11: Zhou 2015 (NMA) | B11: 1.56 | C11: 1.05 | D11: 2.55 | E11: OR | F11: Augmentation | G11: Lithium | H11: Mixed | I11: Response
A12: Bauer 2009 (ONYX) | B12: 1.42 | C12: 1.03 | D12: 1.94 | E12: RR | F12: Augmentation | G12: Quetiapine | H12: Mixed | I12: Remission
A13: Dunner 2007 | B13: 2.5 | C13: 0.31 | D13: 19.99 | E13: RR | F13: Augmentation | G13: Ziprasidone | H13: Mixed | I13: Remission
... A20: Zhou 2015 (NMA) | B20: 1.46 | C20: 0.85 | D20: 2.91 | E20: OR | F20: Augmentation | G20: Lithium | H20: Mixed | I20: Remission
D22: Response | M22: Remission
A35: AUG
A61: COM

Sheet New_meta_ESK
A1: Study | B1: RR | C1: Lower | D1: Upper | E1: type
A2: Fedgchin 2019_TRANSFORM-1 | B2: 1.378 | C2: 1.062 | D2: 1.788 | E2: Response
A3: Popova_2019_TRANSFORM-2 | B3: 1.333 | C3: 1.06 | D3: 1.675 | E3: Response
A4: Fedgchin 2019_TRANSFORM-1 | B4: 1.222 | C4: 0.884 | D4: 1.69 | E4: Remission
A5: Popova_2019_TRANSFORM-2 | B5: 1.693 | C5: 1.197 | D5: 2.393 | E5: Remission
D14: Response | P14: Remission

Sheet Drug_costs
A1: Variable | B1: Unit cost | C1: Variable | D1: Dose per unit (mg)
A2: esketamine_ucost | B2: 1304 | C2: esketamine_udose | D2: 28 | F2: Lithium_ucost | G2: 7.2775 | H2: Lithium_udose | I2: 400
A3: olanzapine_ucost | B3: 0.35 | C3: olanzapine_udose | D3: 5
A4: mirtazapine_ucost | B4: 0.34 | C4: mirtazapine_udose | D4: 15
A5: mianserin_ucost | B5: 0.7752 | C5: mianserin_udose | D5: 30
A6: cariprazine_ucost | B6: 1 | C6: cariprazine_udose | D6: 1.5
A7: quetiapine_ucost | B7: 0.1583 | C7: quetiapine_udose | D7: 25
A8: ziprasidone_ucost | B8: 4.2041 | C8: ziprasidone_udose | D8: 20
A10: Esketamine RCT | B10: TRANSFORM-1 | C10: TRANSFORM-2 | E10: Mirtazapine RCT* | F10: Kessler 2018 | H10: Cariprazine RCT* | I10: Durgam 2016 | K10: Quetiapine RCT^ | L10: Bauer 2009 | N10: Ziprasidone RCT^ | O10: Dunner 2007
A11: Induction phase (4 weeks) | E11: Dose (mg) per week (week 1-2) | F11: =15*7 -> 105 | H11: Group 1 (1-2 mg) | K11: Group 1 (150 mg) | N11: Group 1 (80 mg)
A12: Group 1 (56 mg) | E12: Dose (mg) per week (week 3 and onwards) | F12: =15*2*7 -> 210 | H12: n | I12: 273 | K12: n | L12: 166 | N12: n | O12: 21
A13: n | B13: 115 | C13: 58 | E13: Dose (mg) of 12 weeks | F13: =F11*2+F12*10 -> 2310 | H13: Mean daily dose | I13: 1.4 | K13: Mean daily dose | L13: 150 | N13: Mean daily dose | O13: 80
A14: Dose (mg) per week | B14: =28*2*2 -> 112 | C14: =28*2*2 -> 112 | E14: Mean daily dose (mg) | F14: =F13/12/7 -> 27.5 | H14: Mean dose per cycle | I14: =I13*28 -> 39.2 | K14: Mean dose per cycle | L14: =L13*28 -> 4200 | N14: Mean dose per cycle | O14: =O13*28 -> 2240
A15: Dose (mg) per cycle | B15: =B14*4 -> 448 | C15: =C14*4 -> 448 | E15: Dose (mg) per cycle | F15: =F13/12*4 -> 770 | H15: Cost per cycle | I15: =I14/cariprazine_udose*cariprazine_ucost -> 26.133333 | K15: Cost per cycle | L15: =L14/quetiapine_udose*quetiapine_ucost -> 26.5944 | N15: Cost per cycle | O15: =O14/ziprasidone_udose*ziprasidone_ucost -> 470.8592
A16: Cost per cycle | B16: =B15/esketamine_udose*esketamine_ucost -> 20864 | C16: =C15/esketamine_udose*esketamine_ucost -> 20864 | H16: Weight | I16: =I12/SUM(I12,I19) -> 0.50183824 | K16: Weight | L16: =L12/SUM(L12,L19) -> 0.50764526 | N16: Weight | O16: =O12/SUM(O12,O19) -> 0.525
A17: Weight | B17: =B13/SUM(B13,B20) -> 0.50218341 | C17: =C13/SUM(C13,C20) -> 0.54205607 | E17: Cost per cycle | F17: =F15/mirtazapine_udose*mirtazapine_ucost -> 17.453333
E18: Weight in meta-analysis | F18: 0.7283 | H18: Group 2 (2-4 mg) | K18: Group 2 (300 mg) | N18: Group 2 (160 mg)
A19: Group 2 (84 mg) | H19: n | I19: 271 | K19: n | L19: 161 | N19: n | O19: 19
A20: n | B20: 114 | C20: 49 | H20: Mean daily dose | I20: 2.6 | K20: Mean daily dose | L20: 300 | N20: Mean daily dose | O20: 160
A21: Dose (mg) per week (week 1) | B21: =28*2+28*3 -> 140 | C21: =28*2+28*3 -> 140 | H21: Mean dose per cycle | I21: =I20*28 -> 72.8 | K21: Mean dose per cycle | L21: =L20*28 -> 8400 | N21: Mean dose per cycle | O21: =O20*28 -> 4480
A22: Dose (mg) per week (week 2-4) | B22: =28*3*2 -> 168 | C22: =28*3*2 -> 168 | H22: Cost per cycle | I22: =I21/cariprazine_udose*cariprazine_ucost -> 48.533333 | K22: Cost per cycle | L22: =L21/quetiapine_udose*quetiapine_ucost -> 53.1888 | N22: Cost per cycle | O22: =O21/ziprasidone_udose*ziprasidone_ucost -> 941.7184
A23: Dose (mg) per cycle | B23: =B21+B22*3 -> 644 | C23: =C21+C22*3 -> 644 | E23: Mianserin | F23: Ferrari 2001 | H23: Weight | I23: =I19/SUM(I12,I19) -> 0.49816176 | K23: Weight | L23: =L19/SUM(L12,L19) -> 0.49235474 | N23: Weight | O23: =O19/SUM(O12,O19) -> 0.475
A24: Cost per cycle | B24: =B23/esketamine_udose*esketamine_ucost -> 29992 | C24: =C23/esketamine_udose*esketamine_ucost -> 29992 | E24: Dose (mg) per week | F24: =60*7 -> 420
A25: Weight | B25: =B20/SUM(B13,B20) -> 0.49781659 | C25: =C20/SUM(C13,C20) -> 0.45794393 | E25: Dose (mg) per cycle | F25: =F24*4 -> 1680 | H25: Weighted dose per cycle | I25: =I14*I16+I21*I23 -> 55.938235 | K25: Weighted dose per cycle | L25: =L14*L16+L21*L23 -> 6267.8899 | N25: Weighted dose per cycle | O25: =O14*O16+O21*O23 -> 3304
H26: Weighted cost per cycle | I26: =I15*I16+I22*I23 -> 37.292157 | K26: Weighted cost per cycle | L26: =L15*L16+L22*L23 -> 39.688279 | N26: Weighted cost per cycle | O26: =O15*O16+O22*O23 -> 694.51732
A27: Weighted devices per cycle | B27: =B23/esketamine_udose*B25+B15/esketamine_udose*B17 -> 19.484716 | C27: =C23/esketamine_udose*C25+C15/esketamine_udose*C17 -> 19.205607 | E27: Cost per cycle | F27: =F25/mianserin_udose*mianserin_ucost -> 43.4112
A28: Weighted cost per cycle | B28: =B16*B17+B24*B25 -> 25408.07 | C28: =C16*C17+C24*C25 -> 25044.112 | E28: Weight in meta-analysis | F28: 0.2717 | H28: Weight in meta-analysis | I28: 0.4081 | K28: Weight in meta-analysis | L28: 0.1935 | N28: Weight in meta-analysis | O28: 0.0045
A30: Weight in meta-analysis | B30: 0.4355 | C30: 0.5645
A31: Pooled devices in cycle 1 | B31: =B27*B30+C27*C30 -> 19.327159
A32: Pooled cost of cycle 1 | B32: =B28*B30+C28*C30 -> 25202.616 | E32: Pooled cost per cycle | F32: =F17*F18+F27*F28 -> 24.506086 | K32: Quetiapine RCT* | L32: El-Khalili 2010 | N32: Ziprasidone RCT* | O32: Papakostas 2015
K33: Group 1 (150 mg) | N33: Mean daily dose | O33: 98
A34: Maintenance phase (4 weeks) | H34: Olazapine RCT* | I34: Shelton 2001 | K34: n | L34: 143 | N34: Mean dose per cycle | O34: =O33*28 -> 2744
A35: Group 1 (56 mg) | H35: Mean daily dose | I35: 13.5 | K35: Dose (mg) per week (week 1) | L35: =50*2+150*5 -> 850 | N35: Cost per cycle | O35: =O34/ziprasidone_udose*ziprasidone_ucost -> 576.80252
A36: n | B36: 115 | C36: 58 | H36: Mean dose per cycle | I36: =I35*28 -> 378 | K36: Dose (mg) per week (week 2 and onwards) | L36: =150*7 -> 1050
A37: Dose (mg) per week | B37: =28*2*1 -> 56 | C37: =28*2*1 -> 56 | H37: Cost per cycle | I37: =I36/olanzapine_udose*olanzapine_ucost -> 26.46 | K37: Dose (mg) of 6 weeks | L37: =L35+L36*5 -> 6100 | N37: Weight in meta-analysis | O37: 0.0889
A38: Dose (mg) per cycle | B38: =B37*4 -> 224 | C38: =C37*4 -> 224 | K38: Mean daily dose (mg) | L38: =L37/6/7 -> 145.2381
A39: Cost per cycle | B39: =B38/esketamine_udose*esketamine_ucost -> 10432 | C39: =C38/esketamine_udose*esketamine_ucost -> 10432 | H39: Weight in meta-analysis | I39: 0.002 | K39: Dose (mg) per cycle | L39: =L37/6*4 -> 4066.6667
A40: Weight | B40: =B36/SUM(B36,B43) -> 0.50218341 | C40: =C36/SUM(C36,C43) -> 0.54205607 | K40: Cost per cycle | L40: =L39/quetiapine_udose*quetiapine_ucost -> 25.750133
K41: Weight | L41: =L34/SUM(L34,L44) -> 0.47039474
A42: Group 2 (84 mg)
...

Sheet Cost_component
A1: Cost per cycle (28 days) (HKD)
A2: Treatment Arm | B2: Medication Cost | C2: HRU: SOPC Cost | D2: Other HRU (OP/IP) | E2: Non-pharmacological Intervention Cost | F2: Total cost | G2: Reference
A3: AD+AD (COM) | B3: 25 | C3: 1190 | E3: 0 | F3: =B3+C3+E3 -> 1215 | G3: 2
A4: AD+APSY (AUG) | B4: 109 | C4: 1190 | E4: 0 | F4: =B4+C4+E4 -> 1299 | G4: 2
A5: PSY alone | B5: 0 | C5: 1190 | E5: 3,150*1 = 3,150 | F5: 4340 | G5: 2
A6: PSY(+AD) | B6: 12.5 | C6: 1190 | E6: 3,150*1 = 3,150 | F6: 4352.5 | G6: 1
A7: rTMS(+AD) | B7: 12.5 | C7: 1,190*20=23,800 | E7: 3,000*20 = 60,000 | F7: 83812.5 | G7: 2
A8: ESK(+AD) | B8: 1,304*3(dose)*4= 15,648 | C8: 1,190*4=4,760(SOPC); 1,260*4=5,040 (Psychiatric day hospital) | E8: 0 | F8: 25448 | G8: 2
A9: ECT (+AD) | B9: 12.5 | C9: 2,340*28=65,520 | E9: 9,720*8=77,760 | F9: 143292.5 | G9: 1
A13: Cost Range per cycle (28 days) for PSA (HKD)
A14: Treatment Arm | B14: Medication Cost Range | C14: HRU: SOPC Cost Range | D14: Other HRU (OP/IP) | E14: Non-pharmacological Intervention Cost Range
A15: AD+AD (COM) | B15: 25 | C15: 1190 | E15: 0
A16: AD+APSY (AUG) | B16: 109 | C16: 1190 | E16: 0
A17: PSY alone | B17: 0 | C17: 1190 | E17: 2,520 – 3,780 (20% range)
A18: PSY(+AD) | B18: 12.5 | C18: 1190 | E18: 2,520 – 3,780 (20% range)
A19: rTMS(+AD) | B19: 12.5 | C19: 1,190*20=23,800 | E19: 48,000 – 72,000 (20% range)
A20: ESK(+AD) | B20: 1,304*3(dose)*4= 15,648 | C20: 1,190*4=4,760(SOPC); 1,260*4=5,040 (Psychiatric day hospital) | E20: 0
A21: ECT (+AD) | B21: 12.5 | C21: 2,340*28=65,520 | E21: 38,880 – 116,640 (50% range)
A25: Total Cost (5 years) - Per-patient cost (HKD, 5-year)
A26: Treatment Arm | B26: Medication Cost | C26: HRU: SOPC Cost | D26: Other HRU (OP/IP) | E26: Non-pharmacological Intervention Cost | F26: Total cost
A27: AD+AD (COM) | B27: 106.81 | C27: 5084.3 | D27: 120877.07 | E27: 0 | F27: 126068.19
A28: AD+APSY (AUG) | B28: 416.68 | C28: 4549.05 | D28: 121273.48 | E28: 0 | F28: 126239.21
A29: PSY alone | B29: 0 | C29: 8268.71 | D29: 122236.82 | E29: 21887.76 | F29: 152393.29
A30: PSY(+AD) | B30: 35.05 | C30: 13346.2 | D30: 119421.21 | E30: 35328.17 | F30: 168130.63
A31: rTMS(+AD) | B31: 23.45 | C31: 34220.83 | D31: 118222.48 | E31: 86271 | F31: 238737.76
A32: ESK(+AD) | B32: 67411.34 | C32: 42192.37 | D32: 117069.22 | E32: 0 | F32: 226672.93
A33: ECT (+AD) | B33: 24.97 | C33: 126904.07 | D33: 114995.44 | E33: 116556.8 | F33: 358481.28
A40: Reference
A41: [1] Diagnostic / Therapeutic Procedures. (2025). Ha.org.hk. https://www3.ha.org.hk/fnc/DiagnosticTherapeuticProcedures.aspx?lang=ENG
A42: [2] Hospital Authority. (2017). Hospital Authority : Fees and Charges. Www.ha.org.hk. https://www.ha.org.hk/visitor/ha_visitor_index.asp?Content_ID=10045&Lang=ENG

Sheet Life table
A1: Table 115-01021 : Hong Kong Life Tables
A3: Sex | C3: Male | I3: Female
C4: Probability of dying between exact age x and age x+1 | D4: Number of survivors at exact age x | E4: Number of deaths between exact age x and age x+1 | F4: Number of person-years lived between exact age x and age x+1 | G4: Total person-years lived after exact age x | H4: Expectation of life at exact age x | I4: Probability of dying between exact age x and age x+1 | J4: Number of survivors at exact age x | K4: Number of deaths between exact age x and age x+1 | L4: Number of person-years lived between exact age x and age x+1 | M4: Total person-years lived after exact age x | N4: Expectation of life at exact age x
C5: q(x) | D5: l(x) | E5: d(x) | F5: L(x) | G5: T(x) | H5: e(x) | I5: q(x) | J5: l(x) | K5: d(x) | L5: L(x) | M5: T(x) | N5: e(x)
A6: Year | B6: Age x
A7: 2020 | B7: 0 | C7: 0.00223676 | D7: 1000000 | E7: 2237 | F7: 997938 | G7: 83351450 | H7: 83.35 | I7: 0.00143195 | J7: 1000000 | K7: 1432 | L7: 998711 | M7: 87746126 | N7: 87.75
B8: 1 | C8: 0.00025115 | D8: 997763 | E8: 251 | F8: 997638 | G8: 82353512 | H8: 82.54 | I8: 0.00023762 | J8: 998568 | K8: 237 | L8: 998450 | M8: 86747415 | N8: 86.87
B9: 2 | C9: 0.00019646 | D9: 997512 | E9: 196 | F9: 997414 | G9: 81355874 | H9: 81.56 | I9: 0.00018521 | J9: 998331 | K9: 185 | L9: 998239 | M9: 85748965 | N9: 85.89
B10: 3 | C10: 0.00015114 | D10: 997316 | E10: 151 | F10: 997241 | G10: 80358460 | H10: 80.57 | I10: 0.00014168 | J10: 998146 | K10: 141 | L10: 998076 | M10: 84750726 | N10: 84.91
B11: 4 | C11: 0.00011518 | D11: 997165 | E11: 115 | F11: 997108 | G11: 79361219 | H11: 79.59 | I11: 0.00010704 | J11: 998005 | K11: 107 | L11: 997952 | M11: 83752650 | N11: 83.92
B12: 5 | C12: 8.851e-05 | D12: 997050 | E12: 88 | F12: 997006 | G12: 78364111 | H12: 78.6 | I12: 8.118e-05 | J12: 997898 | K12: 81 | L12: 997858 | M12: 82754698 | N12: 82.93
B13: 6 | C13: 7.086e-05 | D13: 996962 | E13: 71 | F13: 996927 | G13: 77367105 | H13: 77.6 | I13: 6.382e-05 | J13: 997817 | K13: 64 | L13: 997785 | M13: 81756840 | N13: 81.94
B14: 7 | C14: 6.183e-05 | D14: 996891 | E14: 62 | F14: 996860 | G14: 76370178 | H14: 76.61 | I14: 5.45e-05 | J14: 997753 | K14: 54 | L14: 997726 | M14: 80759055 | N14: 80.94
B15: 8 | C15: 6.063e-05 | D15: 996829 | E15: 60 | F15: 996799 | G15: 75373318 | H15: 75.61 | I15: 5.238e-05 | J15: 997699 | K15: 52 | L15: 997673 | M15: 79761329 | N15: 79.95
B16: 9 | C16: 6.609e-05 | D16: 996769 | E16: 66 | F16: 996736 | G16: 74376519 | H16: 74.62 | I16: 5.614e-05 | J16: 997647 | K16: 56 | L16: 997619 | M16: 78763656 | N16: 78.95
B17: 10 | C17: 7.694e-05 | D17: 996703 | E17: 77 | F17: 996665 | G17: 73379783 | H17: 73.62 | I17: 6.439e-05 | J17: 997591 | K17: 64 | L17: 997559 | M17: 77766037 | N17: 77.95
B18: 11 | C18: 9.164e-05 | D18: 996626 | E18: 91 | F18: 996581 | G18: 72383118 | H18: 72.63 | I18: 7.546e-05 | J18: 997527 | K18: 75 | L18: 997490 | M18: 76768478 | N18: 76.96
B19: 12 | C19: 0.00010861 | D19: 996535 | E19: 108 | F19: 996481 | G19: 71386537 | H19: 71.63 | I19: 8.761e-05 | J19: 997452 | K19: 87 | L19: 997409 | M19: 75770988 | N19: 75.96
... B107: 100+ (1) | C107: 1 | D107: 116302 | E107: 116302 | F107: 620317 | G107: 620317 | H107: 5.33 | I107: 1 | J107: 117528 | K107: 117528 | L107: 361842 | M107: 361842 | N107: 3.08
A108: 2021 | B108: 0 | C108: 0.0014076 | D108: 1000000 | E108: 1408 | F108: 998696 | G108: 83240021 | H108: 83.24 | I108: 0.0012574 | J108: 1000000 | K108: 1257 | L108: 998907 | M108: 87939507 | N108: 87.94
B109: 1 | C109: 0.00021067 | D109: 998592 | E109: 210 | F109: 998487 | G109: 82241325 | H109: 82.36 | I109: 0.00023209 | J109: 998743 | K109: 232 | L109: 998627 | M109: 86940600 | N109: 87.05
B110: 2 | C110: 0.00016593 | D110: 998382 | E110: 166 | F110: 998299 | G110: 81242838 | H110: 81.37 | I110: 0.00018715 | J110: 998511 | K110: 187 | L110: 998418 | M110: 85941973 | N110: 86.07
B111: 3 | C111: 0.00012966 | D111: 998216 | E111: 129 | F111: 998152 | G111: 80244539 | H111: 80.39 | I111: 0.00014959 | J111: 998324 | K111: 149 | L111: 998250 | M111: 84943555 | N111: 85.09
B112: 4 | C112: 0.00010187 | D112: 998087 | E112: 102 | F112: 998036 | G112: 79246387 | H112: 79.4 | I112: 0.00011942 | J112: 998175 | K112: 119 | L112: 998116 | M112: 83945305 | N112: 84.1
B113: 5 | C113: 8.241e-05 | D113: 997985 | E113: 82 | F113: 997944 | G113: 78248351 | H113: 78.41 | I113: 9.657e-05 | J113: 998056 | K113: 96 | L113: 998008 | M113: 82947189 | N113: 83.11
B114: 6 | C114: 7.096e-05 | D114: 997903 | E114: 71 | F114: 997868 | G114: 77250407 | H114: 77.41 | I114: 8.086e-05 | J114: 997960 | K114: 81 | L114: 997920 | M114: 81949181 | N114: 82.12
B115: 7 | C115: 6.711e-05 | D115: 997832 | E115: 67 | F115: 997799 | G115: 76252539 | H115: 76.42 | I115: 7.192e-05 | J115: 997879 | K115: 72 | L115: 997843 | M115: 80951261 | N115: 81.12
B116: 8 | C116: 6.989e-05 | D116: 997765 | E116: 70 | F116: 997730 | G116: 75254740 | H116: 75.42 | I116: 6.916e-05 | J116: 997807 | K116: 69 | L116: 997773 | M116: 79953418 | N116: 80.13
B117: 9 | C117: 7.793e-05 | D117: 997695 | E117: 78 | F117: 997656 | G117: 74257010 | H117: 74.43 | I117: 7.165e-05 | J117: 997738 | K117: 71 | L117: 997703 | M117: 78955645 | N117: 79.13
B118: 10 | C118: 8.981e-05 | D118: 997617 | E118: 90 | F118: 997572 | G118: 73259354 | H118: 73.43 | I118: 7.832e-05 | J118: 997667 | K118: 78 | L118: 997628 | M118: 77957942 | N118: 78.14
B119: 11 | C119: 0.00010398 | D119: 997527 | E119: 104 | F119: 997475 | G119: 72261782 | H119: 72.44 | I119: 8.785e-05 | J119: 997589 | K119: 88 | L119: 997545 | M119: 76960314 | N119: 77.15
B120: 12 | C120: 0.00011898 | D120: 997423 | E120: 119 | F120: 997364 | G120: 71264307 | H120: 71.45 | I120: 9.877e-05 | J120: 997501 | K120: 99 | L120: 997452 | M120: 75962769 | N120: 76.15
... B208: 100+ (1) | C208: 1 | D208: 95377 | E208: 95377 | F208: 405766 | G208: 405766 | H208: 4.25 | I208: 1 | J208: 122637 | K208: 122637 | L208: 382547 | M208: 382547 | N208: 3.12
A209: 2022 ‡‡ | B209: 0 | C209: 0.00193327 | D209: 1000000 | E209: 1933 | F209: 998301 | G209: 80698271 | H209: 80.7 | I209: 0.0014992 | J209: 1000000 | K209: 1499 | L209: 998751 | M209: 86771821 | N209: 86.77
B210: 1 | C210: 0.00065285 | D210: 998067 | E210: 652 | F210: 997741 | G210: 79699970 | H210: 79.85 | I210: 0.00046371 | J210: 998501 | K210: 463 | L210: 998270 | M210: 85773070 | N210: 85.9
B211: 2 | C211: 0.00050797 | D211: 997415 | E211: 507 | F211: 997162 | G211: 78702229 | H211: 78.91 | I211: 0.00036141 | J211: 998038 | K211: 361 | L211: 997858 | M211: 84774800 | N211: 84.94
B212: 3 | C212: 0.00038285 | D212: 996908 | E212: 382 | F212: 996717 | G212: 77705067 | H212: 77.95 | I212: 0.00027365 | J212: 997677 | K212: 273 | L212: 997541 | M212: 83776942 | N212: 83.97
B213: 4 | C213: 0.0002775 | D213: 996526 | E213: 277 | F213: 996388 | G213: 76708350 | H213: 76.98 | I213: 0.00020045 | J213: 997404 | K213: 200 | L213: 997304 | M213: 82779401 | N213: 82.99
B214: 5 | C214: 0.00019194 | D214: 996249 | E214: 191 | F214: 996154 | G214: 75711962 | H214: 76 | I214: 0.00014174 | J214: 997204 | K214: 141 | L214: 997134 | M214: 81782097 | N214: 82.01
B215: 6 | C215: 0.00012608 | D215: 996058 | E215: 126 | F215: 995995 | G215: 74715808 | H215: 75.01 | I215: 9.729e-05 | J215: 997063 | K215: 97 | L215: 997015 | M215: 80784963 | N215: 81.02
...

Sheet Hypothetical population
D1: Age | E1: Female | F1: Roundup | G1: Age_abs | H1: Female_abs | I1: Eligible | J1: Mortality | M1: LT_Age | N1: LT_Male | O1: LT_Female
A2: Hypothetical population | D2: =NORMINV(RAND(), mean_age, sd_age) -> 54.502863 | E2: =_xlfn.BINOM.INV(1, prop_female, RAND()) -> 0 | F2: =ROUND(G2,0) -> 49 | G2: 49 | H2: 1 | I2: =IF(G2<18, 0, 1) -> 1 | J2: =IF(H2=0,VLOOKUP(G2,$M$2:$O$102,2,TRUE),VLOOKUP(G2,$M$2:$O$102,3,TRUE)) -> 0.00118774 | M2: 0 | N2: ='Life table'!C310 -> 0.00149875 | O2: ='Life table'!I310 -> 0.00183459
A3: mean_age | B3: 46.6 | D3: =NORMINV(RAND(), mean_age, sd_age) -> 39.138433 | E3: =_xlfn.BINOM.INV(1, prop_female, RAND()) -> 1 | F3: =ROUND(G3,0) -> 40 | G3: 40 | H3: 0 | I3: =IF(G3<18, 0, 1) -> 1 | J3: =IF(H3=0,VLOOKUP(G3,$M$2:$O$102,2,TRUE),VLOOKUP(G3,$M$2:$O$102,3,TRUE)) -> 0.00103474 | M3: 1 | N3: ='Life table'!C311 -> 0.00017688 | O3: ='Life table'!I311 -> 0.00013137
A4: sd_age | B4: 17.8 | D4: =NORMINV(RAND(), mean_age, sd_age) -> 62.267134 | E4: =_xlfn.BINOM.INV(1, prop_female, RAND()) -> 1 | F4: =ROUND(G4,0) -> 52 | G4: 52 | H4: 0 | I4: =IF(G4<18, 0, 1) -> 1 | J4: =IF(H4=0,VLOOKUP(G4,$M$2:$O$102,2,TRUE),VLOOKUP(G4,$M$2:$O$102,3,TRUE)) -> 0.00338747 | M4: 2 | N4: ='Life table'!C312 -> 0.0001489 | O4: ='Life table'!I312 -> 0.00011612
A5: prop_female | B5: 0.746 | D5: =NORMINV(RAND(), mean_age, sd_age) -> 51.249688 | E5: =_xlfn.BINOM.INV(1, prop_female, RAND()) -> 0 | F5: =ROUND(G5,0) -> 41 | G5: 41 | H5: 1 | I5: =IF(G5<18, 0, 1) -> 1 | J5: =IF(H5=0,VLOOKUP(G5,$M$2:$O$102,2,TRUE),VLOOKUP(G5,$M$2:$O$102,3,TRUE)) -> 0.00056607 | M5: 3 | N5: ='Life table'!C313 -> 0.00012517 | O5: ='Life table'!I313 -> 0.00010444
D6: =NORMINV(RAND(), mean_age, sd_age) -> 49.728255 | E6: =_xlfn.BINOM.INV(1, prop_female, RAND()) -> 1 | F6: =ROUND(G6,0) -> 41 | G6: 41 | H6: 1 | I6: =IF(G6<18, 0, 1) -> 1 | J6: =IF(H6=0,VLOOKUP(G6,$M$2:$O$102,2,TRUE),VLOOKUP(G6,$M$2:$O$102,3,TRUE)) -> 0.00056607 | M6: 4 | N6: ='Life table'!C314 -> 0.00010569 | O6: ='Life table'!I314 -> 9.635e-05
D7: =NORMINV(RAND(), mean_age, sd_age) -> 48.071222 | E7: =_xlfn.BINOM.INV(1, prop_female, RAND()) -> 1 | F7: =ROUND(G7,0) -> 39 | G7: 39 | H7: 1 | I7: =IF(G7<18, 0, 1) -> 1 | J7: =IF(H7=0,VLOOKUP(G7,$M$2:$O$102,2,TRUE),VLOOKUP(G7,$M$2:$O$102,3,TRUE)) -> 0.00048623 | M7: 5 | N7: ='Life table'!C315 -> 9.065e-05 | O7: ='Life table'!I315 -> 9.175e-05
A8: Simulated population | D8: =NORMINV(RAND(), mean_age, sd_age) -> 64.651873 | E8: =_xlfn.BINOM.INV(1, prop_female, RAND()) -> 1 | F8: =ROUND(G8,0) -> 61 | G8: 61 | H8: 1 | I8: =IF(G8<18, 0, 1) -> 1 | J8: =IF(H8=0,VLOOKUP(G8,$M$2:$O$102,2,TRUE),VLOOKUP(G8,$M$2:$O$102,3,TRUE)) -> 0.00328762 | M8: 6 | N8: ='Life table'!C316 -> 8.042e-05 | O8: ='Life table'!I316 -> 9.046e-05
A9: mean age | B9: =SUMIF(I2:I1000, 1, G2:G1000)/COUNTIF(I2:I1000, 1) -> 48.697452 | D9: =NORMINV(RAND(), mean_age, sd_age) -> 28.536652 | E9: =_xlfn.BINOM.INV(1, prop_female, RAND()) -> 1 | F9: =ROUND(G9,0) -> 32 | G9: 32 | H9: 1 | I9: =IF(G9<18, 0, 1) -> 1 | J9: =IF(H9=0,VLOOKUP(G9,$M$2:$O$102,2,TRUE),VLOOKUP(G9,$M$2:$O$102,3,TRUE)) -> 0.00031137 | M9: 7 | N9: ='Life table'!C317 -> 7.5e-05 | O9: ='Life table'!I317 -> 9.224e-05
A10: prop female | B10: =SUMIF(I2:I1000, 1, H2:H1000)/COUNTIF(I2:I1000, 1) -> 0.75477707 | D10: =NORMINV(RAND(), mean_age, sd_age) -> 49.789121 | E10: =_xlfn.BINOM.INV(1, prop_female, RAND()) -> 1 | F10: =ROUND(G10,0) -> 42 | G10: 42 | H10: 1 | I10: =IF(G10<18, 0, 1) -> 1 | J10: =IF(H10=0,VLOOKUP(G10,$M$2:$O$102,2,TRUE),VLOOKUP(G10,$M$2:$O$102,3,TRUE)) -> 0.00061161 | M10: 8 | N10: ='Life table'!C318 -> 7.534e-05 | O10: ='Life table'!I318 -> 9.652e-05
A11: Annual mortality | B11: =SUMIF(I2:I1000, 1, J2:J1000)/COUNTIF(I2:I1000, 1) -> 0.0063634714 | D11: =NORMINV(RAND(), mean_age, sd_age) -> 53.367312 | E11: =_xlfn.BINOM.INV(1, prop_female, RAND()) -> 1 | F11: =ROUND(G11,0) -> 52 | G11: 52 | H11: 1 | I11: =IF(G11<18, 0, 1) -> 1 | J11: =IF(H11=0,VLOOKUP(G11,$M$2:$O$102,2,TRUE),VLOOKUP(G11,$M$2:$O$102,3,TRUE)) -> 0.00160396 | M11: 9 | N11: ='Life table'!C319 -> 8.238e-05 | O11: ='Life table'!I319 -> 0.00010249
A12: Annual mortality as TRD | B12: =B11*1.58*1.51 -> 0.01518197 | D12: =NORMINV(RAND(), mean_age, sd_age) -> 39.126563 | E12: =_xlfn.BINOM.INV(1, prop_female, RAND()) -> 1 | F12: =ROUND(G12,0) -> 42 | G12: 42 | H12: 1 | I12: =IF(G12<18, 0, 1) -> 1 | J12: =IF(H12=0,VLOOKUP(G12,$M$2:$O$102,2,TRUE),VLOOKUP(G12,$M$2:$O$102,3,TRUE)) -> 0.00061161 | M12: 10 | N12: ='Life table'!C320 -> 9.687e-05 | O12: ='Life table'!I320 -> 0.00010935
D13: =NORMINV(RAND(), mean_age, sd_age) -> 44.745573 | E13: =_xlfn.BINOM.INV(1, prop_female, RAND()) -> 1 | F13: =ROUND(G13,0) -> 45 | G13: 45 | H13: 1 | I13: =IF(G13<18, 0, 1) -> 1 | J13: =IF(H13=0,VLOOKUP(G13,$M$2:$O$102,2,TRUE),VLOOKUP(G13,$M$2:$O$102,3,TRUE)) -> 0.00079023 | M13: 11 | N13: ='Life table'!C321 -> 0.00011922 | O13: ='Life table'!I321 -> 0.00011621
D14: =NORMINV(RAND(), mean_age, sd_age) -> 50.703018 | E14: =_xlfn.BINOM.INV(1, prop_female, RAND()) -> 0 | F14: =ROUND(G14,0) -> 66 | G14: 66 | H14: 1 | I14: =IF(G14<18, 0, 1) -> 1 | J14: =IF(H14=0,VLOOKUP(G14,$M$2:$O$102,2,TRUE),VLOOKUP(G14,$M$2:$O$102,3,TRUE)) -> 0.00471198 | M14: 12 | N14: ='Life table'!C322 -> 0.00014908 | O14: ='Life table'!I322 -> 0.00012228
D15: =NORMINV(RAND(), mean_age, sd_age) -> 29.73491 | E15: =_xlfn.BINOM.INV(1, prop_female, RAND()) -> 1 | F15: =ROUND(G15,0) -> 46 | G15: 46 | H15: 1 | I15: =IF(G15<18, 0, 1) -> 1 | J15: =IF(H15=0,VLOOKUP(G15,$M$2:$O$102,2,TRUE),VLOOKUP(G15,$M$2:$O$102,3,TRUE)) -> 0.0008706 | M15: 13 | N15: ='Life table'!C323 -> 0.00018462 | O15: ='Life table'!I323 -> 0.00012722
D16: =NORMINV(RAND(), mean_age, sd_age) -> 37.563463 | E16: =_xlfn.BINOM.INV(1, prop_female, RAND()) -> 1 | F16: =ROUND(G16,0) -> 23 | G16: 23 | H16: 0 | I16: =IF(G16<18, 0, 1) -> 1 | J16: =IF(H16=0,VLOOKUP(G16,$M$2:$O$102,2,TRUE),VLOOKUP(G16,$M$2:$O$102,3,TRUE)) -> 0.00031492 | M16: 14 | N16: ='Life table'!C324 -> 0.0002231 | O16: ='Life table'!I324 -> 0.00013109
D17: =NORMINV(RAND(), mean_age, sd_age) -> 44.253371 | E17: =_xlfn.BINOM.INV(1, prop_female, RAND()) -> 0 | F17: =ROUND(G17,0) -> 20 | G17: 20 | H17: 1 | I17: =IF(G17<18, 0, 1) -> 1 | J17: =IF(H17=0,VLOOKUP(G17,$M$2:$O$102,2,TRUE),VLOOKUP(G17,$M$2:$O$102,3,TRUE)) -> 0.00016644 | M17: 15 | N17: ='Life table'!C325 -> 0.00025823 | O17: ='Life table'!I325 -> 0.00013403
D18: =NORMINV(RAND(), mean_age, sd_age) -> 83.954828 | E18: =_xlfn.BINOM.INV(1, prop_female, RAND()) -> 1 | F18: =ROUND(G18,0) -> 7 | G18: 7 | H18: 1 | I18: =IF(G18<18, 0, 1) -> 0 | J18: =IF(H18=0,VLOOKUP(G18,$M$2:$O$102,2,TRUE),VLOOKUP(G18,$M$2:$O$102,3,TRUE)) -> 9.224e-05 | M18: 16 | N18: ='Life table'!C326 -> 0.00028579 | O18: ='Life table'!I326 -> 0.00013677
D19: =NORMINV(RAND(), mean_age, sd_age) -> 48.245969 | E19: =_xlfn.BINOM.INV(1, prop_female, RAND()) -> 1 | F19: =ROUND(G19,0) -> 44 | G19: 44 | H19: 1 | I19: =IF(G19<18, 0, 1) -> 1 | J19: =IF(H19=0,VLOOKUP(G19,$M$2:$O$102,2,TRUE),VLOOKUP(G19,$M$2:$O$102,3,TRUE)) -> 0.00072155 | M19: 17 | N19: ='Life table'!C327 -> 0.00030356 | O19: ='Life table'!I327 -> 0.0001406
D20: =NORMINV(RAND(), mean_age, sd_age) -> 47.413241 | E20: =_xlfn.BINOM.INV(1, prop_female, RAND()) -> 0 | F20: =ROUND(G20,0) -> 111 | G20: 111 | H20: 1 | I20: =IF(G20<18, 0, 1) -> 1 | J20: =IF(H20=0,VLOOKUP(G20,$M$2:$O$102,2,TRUE),VLOOKUP(G20,$M$2:$O$102,3,TRUE)) -> 1 | M20: 18 | N20: ='Life table'!C328 -> 0.00031105 | O20: ='Life table'!I328 -> 0.00014617
D21: =NORMINV(RAND(), mean_age, sd_age) -> 49.736061 | E21: =_xlfn.BINOM.INV(1, prop_female, RAND()) -> 1 | F21: =ROUND(G21,0) -> 52 | G21: 52 | H21: 1 | I21: =IF(G21<18, 0, 1) -> 1 | J21: =IF(H21=0,VLOOKUP(G21,$M$2:$O$102,2,TRUE),VLOOKUP(G21,$M$2:$O$102,3,TRUE)) -> 0.00160396 | M21: 19 | N21: ='Life table'!C329 -> 0.00030983 | O21: ='Life table'!I329 -> 0.0001541
D22: =NORMINV(RAND(), mean_age, sd_age) -> 57.976959 | E22: =_xlfn.BINOM.INV(1, prop_female, RAND()) -> 1 | F22: =ROUND(G22,0) -> 49 | G22: 49 | H22: 1 | I22: =IF(G22<18, 0, 1) -> 1 | J22: =IF(H22=0,VLOOKUP(G22,$M$2:$O$102,2,TRUE),VLOOKUP(G22,$M$2:$O$102,3,TRUE)) -> 0.00118774 | M22: 20 | N22: ='Life table'!C330 -> 0.00030442 | O22: ='Life table'!I330 -> 0.00016644
D23: =NORMINV(RAND(), mean_age, sd_age) -> 38.02589 | E23: =_xlfn.BINOM.INV(1, prop_female, RAND()) -> 1 | F23: =ROUND(G23,0) -> 37 | G23: 37 | H23: 0 | I23: =IF(G23<18, 0, 1) -> 1 | J23: =IF(H23=0,VLOOKUP(G23,$M$2:$O$102,2,TRUE),VLOOKUP(G23,$M$2:$O$102,3,TRUE)) -> 0.00083212 | M23: 21 | N23: ='Life table'!C331 -> 0.0003001 | O23: ='Life table'!I331 -> 0.00018384
D24: =NORMINV(RAND(), mean_age, sd_age) -> 14.239763 | E24: =_xlfn.BINOM.INV(1, prop_female, RAND()) -> 0 | F24: =ROUND(G24,0) -> 28 | G24: 28 | H24: 1 | I24: =IF(G24<18, 0, 1) -> 1 | J24: =IF(H24=0,VLOOKUP(G24,$M$2:$O$102,2,TRUE),VLOOKUP(G24,$M$2:$O$102,3,TRUE)) -> 0.00031845 | M24: 22 | N24: ='Life table'!C332 -> 0.00030281 | O24: ='Life table'!I332 -> 0.00020557
... D102: =NORMINV(RAND(), mean_age, sd_age) -> 37.723694 | E102: =_xlfn.BINOM.INV(1, prop_female, RAND()) -> 0 | F102: =ROUND(G102,0) -> 31 | G102: 31 | H102: 1 | I102: =IF(G102<18, 0, 1) -> 1 | J102: =IF(H102=0,VLOOKUP(G102,$M$2:$O$102,2,TRUE),VLOOKUP(G102,$M$2:$O$102,3,TRUE)) -> 0.00031021 | M102: 100 | N102: ='Life table'!C410 -> 1 | O102: ='Life table'!I410 -> 1
D103: =NORMINV(RAND(), mean_age, sd_age) -> 28.333359 | E103: =_xlfn.BINOM.INV(1, prop_female, RAND()) -> 1 | F103: =ROUND(G103,0) -> 65 | G103: 65 | H103: 1 | I103: =IF(G103<18, 0, 1) -> 1 | J103: =IF(H103=0,VLOOKUP(G103,$M$2:$O$102,2,TRUE),VLOOKUP(G103,$M$2:$O$102,3,TRUE)) -> 0.00437442
D104: =NORMINV(RAND(), mean_age, sd_age) -> 77.754807 | E104: =_xlfn.BINOM.INV(1, prop_female, RAND()) -> 1 | F104: =ROUND(G104,0) -> 49 | G104: 49 | H104: 0 | I104: =IF(G104<18, 0, 1) -> 1 | J104: =IF(H104=0,VLOOKUP(G104,$M$2:$O$102,2,TRUE),VLOOKUP(G104,$M$2:$O$102,3,TRUE)) -> 0.00268687
D105: =NORMINV(RAND(), mean_age, sd_age) -> 31.674668 | E105: =_xlfn.BINOM.INV(1, prop_female, RAND()) -> 0 | F105: =ROUND(G105,0) -> 32 | G105: 32 | H105: 1 | I105: =IF(G105<18, 0, 1) -> 1 | J105: =IF(H105=0,VLOOKUP(G105,$M$2:$O$102,2,TRUE),VLOOKUP(G105,$M$2:$O$102,3,TRUE)) -> 0.00031137
D106: =NORMINV(RAND(), mean_age, sd_age) -> 43.899505 | E106: =_xlfn.BINOM.INV(1, prop_female, RAND()) -> 1 | F106: =ROUND(G106,0) -> 48 | G106: 48 | H106: 0 | I106: =IF(G106<18, 0, 1) -> 1 | J106: =IF(H106=0,VLOOKUP(G106,$M$2:$O$102,2,TRUE),VLOOKUP(G106,$M$2:$O$102,3,TRUE)) -> 0.00244746
D107: =NORMINV(RAND(), mean_age, sd_age) -> 73.333999 | E107: =_xlfn.BINOM.INV(1, prop_female, RAND()) -> 1 | F107: =ROUND(G107,0) -> 46 | G107: 46 | H107: 1 | I107: =IF(G107<18, 0, 1) -> 1 | J107: =IF(H107=0,VLOOKUP(G107,$M$2:$O$102,2,TRUE),VLOOKUP(G107,$M$2:$O$102,3,TRUE)) -> 0.0008706
D108: =NORMINV(RAND(), mean_age, sd_age) -> 47.684229 | E108: =_xlfn.BINOM.INV(1, prop_female, RAND()) -> 1 | F108: =ROUND(G108,0) -> 65 | G108: 65 | H108: 1 | I108: =IF(G108<18, 0, 1) -> 1 | J108: =IF(H108=0,VLOOKUP(G108,$M$2:$O$102,2,TRUE),VLOOKUP(G108,$M$2:$O$102,3,TRUE)) -> 0.00437442
D109: =NORMINV(RAND(), mean_age, sd_age) -> 57.481491 | E109: =_xlfn.BINOM.INV(1, prop_female, RAND()) -> 1 | F109: =ROUND(G109,0) -> 47 | G109: 47 | H109: 0 | I109: =IF(G109<18, 0, 1) -> 1 | J109: =IF(H109=0,VLOOKUP(G109,$M$2:$O$102,2,TRUE),VLOOKUP(G109,$M$2:$O$102,3,TRUE)) -> 0.00221482
D110: =NORMINV(RAND(), mean_age, sd_age) -> 39.968792 | E110: =_xlfn.BINOM.INV(1, prop_female, RAND()) -> 0 | F110: =ROUND(G110,0) -> 64 | G110: 64 | H110: 1 | I110: =IF(G110<18, 0, 1) -> 1 | J110: =IF(H110=0,VLOOKUP(G110,$M$2:$O$102,2,TRUE),VLOOKUP(G110,$M$2:$O$102,3,TRUE)) -> 0.00406529
D111: =NORMINV(RAND(), mean_age, sd_age) -> 56.788636 | E111: =_xlfn.BINOM.INV(1, prop_female, RAND()) -> 1 | F111: =ROUND(G111,0) -> 29 | G111: 29 | H111: 1 | I111: =IF(G111<18, 0, 1) -> 1 | J111: =IF(H111=0,VLOOKUP(G111,$M$2:$O$102,2,TRUE),VLOOKUP(G111,$M$2:$O$102,3,TRUE)) -> 0.00031763
D112: =NORMINV(RAND(), mean_age, sd_age) -> 62.0619 | E112: =_xlfn.BINOM.INV(1, prop_female, RAND()) -> 1 | F112: =ROUND(G112,0) -> 54 | G112: 54 | H112: 1 | I112: =IF(G112<18, 0, 1) -> 1 | J112: =IF(H112=0,VLOOKUP(G112,$M$2:$O$102,2,TRUE),VLOOKUP(G112,$M$2:$O$102,3,TRUE)) -> 0.00191864
D113: =NORMINV(RAND(), mean_age, sd_age) -> 94.341708 | E113: =_xlfn.BINOM.INV(1, prop_female, RAND()) -> 1 | F113: =ROUND(G113,0) -> 9 | G113: 9 | H113: 1 | I113: =IF(G113<18, 0, 1) -> 0 | J113: =IF(H113=0,VLOOKUP(G113,$M$2:$O$102,2,TRUE),VLOOKUP(G113,$M$2:$O$102,3,TRUE)) -> 0.00010249
D114: =NORMINV(RAND(), mean_age, sd_age) -> 37.754312 | E114: =_xlfn.BINOM.INV(1, prop_female, RAND()) -> 1 | F114: =ROUND(G114,0) -> 38 | G114: 38 | H114: 0 | I114: =IF(G114<18, 0, 1) -> 1 | J114: =IF(H114=0,VLOOKUP(G114,$M$2:$O$102,2,TRUE),VLOOKUP(G114,$M$2:$O$102,3,TRUE)) -> 0.00088649
... D1000: =NORMINV(RAND(), mean_age, sd_age) -> 42.555083 | E1000: =_xlfn.BINOM.INV(1, prop_female, RAND()) -> 1 | F1000: =ROUND(G1000,0) -> 43 | G1000: 43 | H1000: 1 | I1000: =IF(G1000<18, 0, 1) -> 1 | J1000: =IF(H1000=0,VLOOKUP(G1000,$M$2:$O$102,2,TRUE),VLOOKUP(G1000,$M$2:$O$102,3,TRUE)) -> 0.00066288

Sheet tpTRD2DEAD
A1: tpTRD2DEAD (re-analysis)
A2: Population: All TRD patients
A3: Index date: First diagnosis date of TRD, i.e. date of receipt of the third antidepressant regimen
A4: Censoring: study end, death (outcome)
A5: Formula
A6: fit<-survreg(Surv(time, event) ~ 1, data = temp, dist = 'lognormal')
A7: summary(fit)
A8: explanatory variables | B8: Coef (base case) | C8: Lower range | D8: Upper range | E8: p | F8: Coef (probabilistic)
A9: intercept (meanlog) | B9: 7.698708 | C9: 6.849251 | D9: 8.548164 | E9: <0.001* | F9: =D97 -> 7.012577
A10: log(scale) | B10: 1.3483 | C10: - | D10: - | E10: <0.001* | F10: =D98 -> 1.2440954
A12: Base case values
A13: Survival function: S(t) = 1 - Φ((lnt−μ)/σ)
A14: S(t) in R for the 1st subgroup is given by: 1-plnorm(t, meanlog = fit$coefficients[1]+fit$coefficients[n], sdlog = fit$scale)
A15: Year | B15: S(t) | C15: S(t)_lower | D15: S(t)_upper
A16: 0 | B16: 1 | C16: 1 | D16: 1
A17: 1 | B17: =1-LOGNORMDIST($A17,$B$9,EXP($B$10)) -> 0.97720723 | C17: =1-LOGNORMDIST($A17,$C$9,EXP($B$10)) -> 0.96234918 | D17: =1-LOGNORMDIST($A17,$D$9,EXP($B$10)) -> 0.98678378
A18: 2 | B18: =1-LOGNORMDIST(A18,$B$9,EXP($B$10)) -> 0.96556056 | C18: =1-LOGNORMDIST($A18,$C$9,EXP($B$10)) -> 0.94504806 | D18: =1-LOGNORMDIST($A18,$D$9,EXP($B$10)) -> 0.97931494
A19: 3 | B19: =1-LOGNORMDIST(A19,$B$9,EXP($B$10)) -> 0.95672845 | C19: =1-LOGNORMDIST($A19,$C$9,EXP($B$10)) -> 0.93232506 | D19: =1-LOGNORMDIST($A19,$D$9,EXP($B$10)) -> 0.97347475
A20: 4 | B20: =1-LOGNORMDIST(A20,$B$9,EXP($B$10)) -> 0.94941586 | C20: =1-LOGNORMDIST($A20,$C$9,EXP($B$10)) -> 0.92199624 | D20: =1-LOGNORMDIST($A20,$D$9,EXP($B$10)) -> 0.96854336
A21: 5 | B21: =1-LOGNORMDIST(A21,$B$9,EXP($B$10)) -> 0.94309182 | C21: =1-LOGNORMDIST($A21,$C$9,EXP($B$10)) -> 0.91319285 | D21: =1-LOGNORMDIST($A21,$D$9,EXP($B$10)) -> 0.9642161
A22: 6 | B22: =1-LOGNORMDIST(A22,$B$9,EXP($B$10)) -> 0.93747587 | C22: =1-LOGNORMDIST($A22,$C$9,EXP($B$10)) -> 0.90546516 | D22: =1-LOGNORMDIST($A22,$D$9,EXP($B$10)) -> 0.96032861
A23: 7 | B23: =1-LOGNORMDIST(A23,$B$9,EXP($B$10)) -> 0.93239837 | C23: =1-LOGNORMDIST($A23,$C$9,EXP($B$10)) -> 0.89854529 | D23: =1-LOGNORMDIST($A23,$D$9,EXP($B$10)) -> 0.95677989
A24: 8 | B24: =1-LOGNORMDIST(A24,$B$9,EXP($B$10)) -> 0.92774753 | C24: =1-LOGNORMDIST($A24,$C$9,EXP($B$10)) -> 0.89225882 | D24: =1-LOGNORMDIST($A24,$D$9,EXP($B$10)) -> 0.95350252
A25: 9 | B25: =1-LOGNORMDIST(A25,$B$9,EXP($B$10)) -> 0.92344507 | C25: =1-LOGNORMDIST($A25,$C$9,EXP($B$10)) -> 0.88648492 | D25: =1-LOGNORMDIST($A25,$D$9,EXP($B$10)) -> 0.95044876
A26: 10 | B26: =1-LOGNORMDIST(A26,$B$9,EXP($B$10)) -> 0.91943369 | C26: =1-LOGNORMDIST($A26,$C$9,EXP($B$10)) -> 0.88113592 | D26: =1-LOGNORMDIST($A26,$D$9,EXP($B$10)) -> 0.94758337
A27: 11 | B27: =1-LOGNORMDIST(A27,$B$9,EXP($B$10)) -> 0.91566999 | C27: =1-LOGNORMDIST($A27,$C$9,EXP($B$10)) -> 0.87614593 | D27: =1-LOGNORMDIST($A27,$D$9,EXP($B$10)) -> 0.94487941
A28: 12 | B28: =1-LOGNORMDIST(A28,$B$9,EXP($B$10)) -> 0.91212016 | C28: =1-LOGNORMDIST($A28,$C$9,EXP($B$10)) -> 0.871464 | D28: =1-LOGNORMDIST($A28,$D$9,EXP($B$10)) -> 0.94231576
A29: 13 | B29: =1-LOGNORMDIST(A29,$B$9,EXP($B$10)) -> 0.90875729 | C29: =1-LOGNORMDIST($A29,$C$9,EXP($B$10)) -> 0.86704982 | D29: =1-LOGNORMDIST($A29,$D$9,EXP($B$10)) -> 0.93987549
... A36: 20 | B36: =1-LOGNORMDIST(A36,$B$9,EXP($B$10)) -> 0.88900905 | C36: =1-LOGNORMDIST($A36,$C$9,EXP($B$10)) -> 0.8415109 | D36: =1-LOGNORMDIST($A36,$D$9,EXP($B$10)) -> 0.92532948
A38: Transition probability in any given cycle: P(t) = 1 - S(t)/S(t-u) where u is the cycle length
A39: Year | B39: P(t) | C39: P(t)_lower | D39: P(t)_upper | E39: P(t)_4W | F39: P(t)_lower_4W | G39: P(t)_upper_4W
A40: 1 | B40: =1-B17/B16 -> 0.022792773 | C40: =1-C17/C16 -> 0.03765082 | D40: =1-D17/D16 -> 0.013216217 | E40: =1-EXP(-(-LN(1-B40)/52)*4) -> 0.0017720085 | F40: =1-EXP(-(-LN(1-C40)/52)*4) -> 0.0029477945 | G40: =1-EXP(-(-LN(1-D40)/52)*4) -> 0.0010228864
A41: 2 | B41: =1-B18/B17 -> 0.011918314 | C41: =1-C18/C17 -> 0.017978008 | D41: =1-D18/D17 -> 0.0075688737 | E41: =1-EXP(-(-LN(1-B41)/52)*4) -> 0.00092187533 | F41: =1-EXP(-(-LN(1-C41)/52)*4) -> 0.0013945326 | G41: =1-EXP(-(-LN(1-D41)/52)*4) -> 0.00058426487
A42: 3 | B42: =1-B19/B18 -> 0.0091471377 | C42: =1-C19/C18 -> 0.01346281 | D42: =1-D19/D18 -> 0.0059635489 | E42: =1-EXP(-(-LN(1-B42)/52)*4) -> 0.00070661405 | F42: =1-EXP(-(-LN(1-C42)/52)*4) -> 0.0010420917 | G42: =1-EXP(-(-LN(1-D42)/52)*4) -> 0.000460002
A43: 4 | B43: =1-B20/B19 -> 0.0076433225 | C43: =1-C20/C19 -> 0.011078558 | D43: =1-D20/D19 -> 0.0050657543 | E43: =1-EXP(-(-LN(1-B43)/52)*4) -> 0.0005900322 | F43: =1-EXP(-(-LN(1-C43)/52)*4) -> 0.00085658537 | G43: =1-EXP(-(-LN(1-D43)/52)*4) -> 0.00039058745
A44: 5 | B44: =1-B21/B20 -> 0.0066609808 | C44: =1-C21/C20 -> 0.009548183 | D44: =1-D21/D20 -> 0.0044678039 | E44: =1-EXP(-(-LN(1-B44)/52)*4) -> 0.00051396512 | F44: =1-EXP(-(-LN(1-C44)/52)*4) -> 0.0007377323 | G44: =1-EXP(-(-LN(1-D44)/52)*4) -> 0.00034438794
A45: 6 | B45: =1-B22/B21 -> 0.0059548371 | C45: =1-C22/C21 -> 0.0084622802 | D45: =1-D22/D21 -> 0.004031765 | E45: =1-EXP(-(-LN(1-B45)/52)*4) -> 0.00045932816 | F45: =1-EXP(-(-LN(1-C45)/52)*4) -> 0.00065350088 | G45: =1-EXP(-(-LN(1-D45)/52)*4) -> 0.00031071437
A46: 7 | B46: =1-B23/B22 -> 0.0054161317 | C46: =1-C23/C22 -> 0.0076423381 | D46: =1-D23/D22 -> 0.0036953144 | E46: =1-EXP(-(-LN(1-B46)/52)*4) -> 0.00041767061 | F46: =1-EXP(-(-LN(1-C46)/52)*4) -> 0.00058995594 | G46: =1-EXP(-(-LN(1-D46)/52)*4) -> 0.00028474091
A47: 8 | B47: =1-B24/B23 -> 0.0049880388 | C47: =1-C24/C23 -> 0.0069962685 | D47: =1-D24/D23 -> 0.0034254221 | E47: =1-EXP(-(-LN(1-B47)/52)*4) -> 0.00038458146 | F47: =1-EXP(-(-LN(1-C47)/52)*4) -> 0.00053992013 | G47: =1-EXP(-(-LN(1-D47)/52)*4) -> 0.0002639115
A48: 9 | B48: =1-B25/B24 -> 0.0046375352 | C48: =1-C25/C24 -> 0.0064711043 | D48: =1-D25/D24 -> 0.0032026716 | E48: =1-EXP(-(-LN(1-B48)/52)*4) -> 0.00035749931 | F48: =1-EXP(-(-LN(1-C48)/52)*4) -> 0.00049927015 | G48: =1-EXP(-(-LN(1-D48)/52)*4) -> 0.00024672426
...
